Workbook

Sheet Campgrounds List
A1: Thousand Trails Campgrounds Directory
A2: ="Comprehensive directory of all "&COUNTA(B5:B89)&" Thousand Trails campgrounds across North America" -> Comprehensive directory of all 85 Thousand Trails campgrounds across North America
A4: # | B4: Name | C4: State | D4: Address | E4: City or Town | F4: Zipcode | G4: Notes
A5: 1 | B5: Acton RV Resort (Soledad Canyon) | C5: CA | D5: 4700 Escondido Canyon Rd | E5: Acton | F5: 93510
A6: 2 | B6: Idyllwild RV Resort | C6: CA | D6: 24400 Delano Dr | E6: Idyllwild | F6: 92549
A7: 3 | B7: Lake Minden RV Resort | C7: CA | D7: 1256 Marcum Rd | E7: Nicolaus | F7: 95659 | G7: Added (was missing)
A8: 4 | B8: Lake of the Springs RV Resort | C8: CA | D8: 14152 French Town Rd | E8: Oregon House | F8: 95962 | G8: Added (was missing)
A9: 5 | B9: Morgan Hill RV Resort | C9: CA | D9: 12895 Uvas Rd | E9: Morgan Hill | F9: 95037 | G9: Added (was missing)
A10: 6 | B10: Oakzanita Springs RV Camping Resort | C10: CA | D10: 11053 Highway 79 | E10: Descanso | F10: 91916
A11: 7 | B11: Palm Springs RV Resort | C11: CA | D11: 77500 Varner Rd | E11: Palm Desert | F11: 92211
A12: 8 | B12: Pio Pico RV Resort & Campground | C12: CA | D12: 14615 Otay Lakes Rd | E12: Jamul | F12: 91935
A13: 9 | B13: Ponderosa RV Resort | C13: CA | D13: 7291 Lotus Rd | E13: Lotus | F13: 95651
A14: 10 | B14: Rancho Oso RV & Camping Resort | C14: CA | D14: 3750 Paradise Rd | E14: Santa Barbara | F14: 93105
A15: 11 | B15: Russian River RV Campground | C15: CA | D15: 22500 River Rd | E15: Cloverdale | F15: 95425
A16: 12 | B16: San Benito RV Camping Resort | C16: CA | D16: 16225 Cienega Rd | E16: Paicines | F16: 95043
A17: 13 | B17: Snowflower RV Resort | C17: CA | D17: 41776 Yuba Gap Rd | E17: Emigrant Gap | F17: 95715
A18: 14 | B18: Turtle Beach RV Resort | C18: CA | D18: 7033 W Bowtie Rd | E18: Manteca | F18: 95337
A19: 15 | B19: Wilderness Lakes RV Resort | C19: CA | D19: 30605 Briggs Rd | E19: Menifee | F19: 92584
A20: 16 | B20: Yosemite Lakes RV Resort | C20: CA | D20: 31191 Hardin Flat Rd | E20: Groveland | F20: 95321
A21: 17 | B21: Bend-Sunriver RV Campground | C21: OR | D21: 15720 S Century Dr | E21: Bend | F21: 97707
... A25: 21 | B25: Whalers Rest RV Camping Resort | C25: OR | D25: 50 SE 123rd St | E25: South Beach | F25: 97366
A26: 22 | B26: Whitten Inn / Whalers Rest Annex | C26: OR | D26: 50 SE 123rd St | E26: South Beach | F26: 97366 | G26: Verify: same address as Whalers Rest; may not be a separate campground
A27: 23 | B27: Birch Bay RV Campground | C27: WA | D27: 8418 Harborview Rd | E27: Blaine | F27: 98230
A28: 24 | B28: Chehalis RV Camping Resort | C28: WA | D28: 2228 Centralia Alpha Rd | E28: Chehalis | F28: 98532
A29: 25 | B29: Crescent Bar RV Resort | C29: WA | D29: 9225 Crescent Bar Rd NW | E29: Quincy | F29: 98848
A30: 26 | B30: Grand Creek / Grandy Creek RV Campground | C30: WA | D30: 7370 Russell Rd | E30: Concrete | F30: 98237
A31: 27 | B31: La Conner RV Camping Resort | C31: WA | D31: 16362 Snee Oosh Rd | E31: La Conner | F31: 98257
A32: 28 | B32: Leavenworth RV Campground | C32: WA | D32: 20752 Chiwawa Loop Rd | E32: Leavenworth | F32: 98826
A33: 29 | B33: Little Diamond RV Campground | C33: WA | D33: 1002 N Diamond Lake Rd | E33: Newport | F33: 99156
A34: 30 | B34: Long Beach RV & Camping Resort | C34: WA | D34: 2215 Willow Rd | E34: Seaview | F34: 98644
A35: 31 | B35: Mount Vernon RV Campground | C35: WA | D35: 5409 Highway 9 | E35: Sedro Woolley | F35: 98284
A36: 32 | B36: Oceana RV Resort | C36: WA | D36: 2733 State Route 109 | E36: Ocean City | F36: 98569
A37: 33 | B37: Paradise RV Campground | C37: WA | D37: 253 Harmony Rd | E37: Silver Creek | F37: 98585
A38: 34 | B38: Thunderbird RV Campground | C38: WA | D38: 26702 Ben Howard Rd | E38: Monroe | F38: 98272
A39: 35 | B39: Las Vegas RV Resort | C39: NV | D39: 4295 Boulder Hwy | E39: Las Vegas | F39: 89121
A40: 36 | B40: Verde Valley RV & Camping Resort | C40: AZ | D40: 6400 E.Thousand Trails Rd | E40: Cottonwood | F40: 86326 | G40: Was unnumbered and not counted; now included
A41: 37 | B41: Blue Mesa Recreational Ranch | C41: CO | D41: 27601 West Highway 50 | E41: Gunnison | F41: 81230 | G41: Added (was missing)
A42: 38 | B42: Bay Landing RV Campground | C42: TX | D42: 2305 Highway 380 W | E42: Bridgeport | F42: 76426
A43: 39 | B43: Colorado River RV Campground | C43: TX | D43: 1062 Thousand Trails S | E43: Columbus | F43: 78934
A44: 40 | B44: Lake Conroe RV Camping Resort | C44: TX | D44: 11720 Thousand Trails Way | E44: Willis | F44: 77318
...

Sheet Summary by State
A1: Thousand Trails Locations by State
A3: State | B3: Campground Count
A4: AL | B4: =COUNTIF('Campgrounds List'!C$5:C$89, A4) -> 1
A5: AZ | B5: =COUNTIF('Campgrounds List'!C$5:C$89, A5) -> 1
A6: BC | B6: =COUNTIF('Campgrounds List'!C$5:C$89, A6) -> 1
A7: CA | B7: =COUNTIF('Campgrounds List'!C$5:C$89, A7) -> 17
A8: CO | B8: =COUNTIF('Campgrounds List'!C$5:C$89, A8) -> 1
A9: FL | B9: =COUNTIF('Campgrounds List'!C$5:C$89, A9) -> 3
A10: IL | B10: =COUNTIF('Campgrounds List'!C$5:C$89, A10) -> 1
A11: IN | B11: =COUNTIF('Campgrounds List'!C$5:C$89, A11) -> 2
A12: KY | B12: =COUNTIF('Campgrounds List'!C$5:C$89, A12) -> 1
A13: MA | B13: =COUNTIF('Campgrounds List'!C$5:C$89, A13) -> 2
A14: ME | B14: =COUNTIF('Campgrounds List'!C$5:C$89, A14) -> 1
A15: MI | B15: =COUNTIF('Campgrounds List'!C$5:C$89, A15) -> 2
... A27: WA | B27: =COUNTIF('Campgrounds List'!C$5:C$89, A27) -> 12
A28: Total | B28: =SUM(B4:B27) -> 85
